<robot
  name="quadruped126">
  <link
    name="base_link">
    <inertial>
      <origin
        xyz="8.0205569429892E-06 5.26164614779445E-06 -0.0117536741870582"
        rpy="0 0 0" />
      <mass
        value="1.0967850842884" />
      <inertia
        ixx="0.03222337128397"
        ixy="6.95895978629379E-07"
        ixz="2.73640904079557E-08"
        iyy="0.00867472819211394"
        iyz="1.20297090374644E-07"
        izz="0.0407340457914462" />
    </inertial>
    <visual>
      <origin
        xyz="0 0 0"
        rpy="0 0 0" />
      <geometry>
        <mesh
          filename="package://quadruped126/meshes/base_link.STL" />
      </geometry>
      <material
        name="">
        <color
          rgba="0.792156862745098 0.819607843137255 0.933333333333333 1" />
      </material>
    </visual>
    <collision>
      <origin
        xyz="0 0 0"
        rpy="0 0 0" />
      <geometry>
        <mesh
          filename="package://quadruped126/meshes/base_link.STL" />
      </geometry>
    </collision>
  </link>
  <link
    name="leg1_1">
    <inertial>
      <origin
        xyz="-9.23209685999016E-06 -0.0110295937744908 0.00343371107754448"
        rpy="0 0 0" />
      <mass
        value="0.136916843168961" />
      <inertia
        ixx="0.000229388412602637"
        ixy="-3.46718755959948E-08"
        ixz="-4.50241112988627E-09"
        iyy="0.000216643146747715"
        iyz="-6.85902650915644E-06"
        izz="0.000193488021134694" />
    </inertial>
    <visual>
      <origin
        xyz="0 0 0"
        rpy="0 0 0" />
      <geometry>
        <mesh
          filename="package://quadruped126/meshes/leg1_1.STL" />
      </geometry>
      <material
        name="">
        <color
          rgba="0.792156862745098 0.819607843137255 0.933333333333333 1" />
      </material>
    </visual>
    <collision>
      <origin
        xyz="0 0 0"
        rpy="0 0 0" />
      <geometry>
        <mesh
          filename="package://quadruped126/meshes/leg1_1.STL" />
      </geometry>
    </collision>
  </link>
  <joint
    name="leg1_1_joint"
    type="revolute">
    <origin
      xyz="0.155 -0.2 -0.0745"
      rpy="-4.6415388888942E-32 -8.28607345441151E-17 5.60161446121751E-16" />
    <parent
      link="base_link" />
    <child
      link="leg1_1" />
    <axis
      xyz="0 0 1" />
  </joint>
  <link
    name="leg1_2">
    <inertial>
      <origin
        xyz="0.0117973861206457 1.03683017630835E-05 0.109124835353205"
        rpy="0 0 0" />
      <mass
        value="0.139285865723" />
      <inertia
        ixx="0.000230964268899526"
        ixy="-3.48586088604811E-08"
        ixz="-7.22110905522625E-06"
        iyy="0.000240608976769206"
        iyz="-6.60780844287011E-09"
        izz="0.000204330642068317" />
    </inertial>
    <visual>
      <origin
        xyz="0 0 0"
        rpy="0 0 0" />
      <geometry>
        <mesh
          filename="package://quadruped126/meshes/leg1_2.STL" />
      </geometry>
      <material
        name="">
        <color
          rgba="0.792156862745098 0.819607843137255 0.933333333333333 1" />
      </material>
    </visual>
    <collision>
      <origin
        xyz="0 0 0"
        rpy="0 0 0" />
      <geometry>
        <mesh
          filename="package://quadruped126/meshes/leg1_2.STL" />
      </geometry>
    </collision>
  </link>
  <joint
    name="leg1_2_joint"
    type="revolute">
    <origin
      xyz="0 0 0"
      rpy="1.5707963267949 -1.90344085017298E-15 -1.55714409358079E-16" />
    <parent
      link="leg1_1" />
    <child
      link="leg1_2" />
    <axis
      xyz="0 0 -1" />
  </joint>
  <link
    name="leg1_3">
    <inertial>
      <origin
        xyz="-0.112501231278763 1.3272460803293E-05 0.110000027562196"
        rpy="0 0 0" />
      <mass
        value="0.422583469922345" />
      <inertia
        ixx="0.000984455636837673"
        ixy="-1.55958083220612E-08"
        ixz="3.442442696051E-05"
        iyy="0.00493486162041129"
        iyz="2.80759528073749E-09"
        izz="0.00483276076809413" />
    </inertial>
    <visual>
      <origin
        xyz="0 0 0"
        rpy="0 0 0" />
      <geometry>
        <mesh
          filename="package://quadruped126/meshes/leg1_3.STL" />
      </geometry>
      <material
        name="">
        <color
          rgba="0.792156862745098 0.819607843137255 0.933333333333333 1" />
      </material>
    </visual>
    <collision>
      <origin
        xyz="0 0 0"
        rpy="0 0 0" />
      <geometry>
        <mesh
          filename="package://quadruped126/meshes/leg1_3.STL" />
      </geometry>
    </collision>
  </link>
  <joint
    name="leg1_3_joint"
    type="revolute">
    <origin
      xyz="0 0 0.1125"
      rpy="1.5707963267949 2.61845052977631E-16 1.57079632679489" />
    <parent
      link="leg1_2" />
    <child
      link="leg1_3" />
    <axis
      xyz="0 0 -1" />
  </joint>
  <link
    name="leg1_4">
    <inertial>
      <origin
        xyz="0.144566617935957 -2.45928618913815E-07 0.037420492901852"
        rpy="0 0 0" />
      <mass
        value="0.418000056329837" />
      <inertia
        ixx="0.000786088948883853"
        ixy="-3.04294740643487E-09"
        ixz="0.00125672996610802"
        iyy="0.00467553600029081"
        iyz="-1.72935257188111E-09"
        izz="0.0042672560924322" />
    </inertial>
    <visual>
      <origin
        xyz="0 0 0"
        rpy="0 0 0" />
      <geometry>
        <mesh
          filename="package://quadruped126/meshes/leg1_4.STL" />
      </geometry>
      <material
        name="">
        <color
          rgba="0.792156862745098 0.819607843137255 0.933333333333333 1" />
      </material>
    </visual>
    <collision>
      <origin
        xyz="0 0 0"
        rpy="0 0 0" />
      <geometry>
        <mesh
          filename="package://quadruped126/meshes/leg1_4.STL" />
      </geometry>
    </collision>
  </link>
  <joint
    name="leg1_4_joint"
    type="revolute">
    <origin
      xyz="-0.225 0 0.11"
      rpy="3.10765853089466E-16 0 3.14159265358979" />
    <parent
      link="leg1_3" />
    <child
      link="leg1_4" />
    <axis
      xyz="0 0 -1" />
  </joint>
  <link
    name="leg2-1">
    <inertial>
      <origin
        xyz="-9.23248238222929E-06 -0.0110295936183098 0.00343371080325661"
        rpy="0 0 0" />
      <mass
        value="0.136916844125613" />
      <inertia
        ixx="0.000229388410138031"
        ixy="-3.46713291307469E-08"
        ixz="-4.5035212742197E-09"
        iyy="0.000216643147863652"
        iyz="-6.85902749279484E-06"
        izz="0.000193488023621699" />
    </inertial>
    <visual>
      <origin
        xyz="0 0 0"
        rpy="0 0 0" />
      <geometry>
        <mesh
          filename="package://quadruped126/meshes/leg2-1.STL" />
      </geometry>
      <material
        name="">
        <color
          rgba="0.792156862745098 0.819607843137255 0.933333333333333 1" />
      </material>
    </visual>
    <collision>
      <origin
        xyz="0 0 0"
        rpy="0 0 0" />
      <geometry>
        <mesh
          filename="package://quadruped126/meshes/leg2-1.STL" />
      </geometry>
    </collision>
  </link>
  <joint
    name="leg2-1_joint"
    type="revolute">
    <origin
      xyz="-0.155 -0.2 -0.0745"
      rpy="2.09476042382105E-15 -8.28607345441156E-17 3.40397411368685E-16" />
    <parent
      link="base_link" />
    <child
      link="leg2-1" />
    <axis
      xyz="0 0 1" />
  </joint>
  <link
    name="leg2_2">
    <inertial>
      <origin
        xyz="-0.0117973861206455 -1.03683017630002E-05 0.109124835353205"
        rpy="0 0 0" />
      <mass
        value="0.139285865722999" />
      <inertia
        ixx="0.000230964268899525"
        ixy="-3.48586088603628E-08"
        ixz="7.2211090552262E-06"
        iyy="0.000240608976769204"
        iyz="6.60780844308423E-09"
        izz="0.000204330642068317" />
    </inertial>
    <visual>
      <origin
        xyz="0 0 0"
        rpy="0 0 0" />
      <geometry>
        <mesh
          filename="package://quadruped126/meshes/leg2_2.STL" />
      </geometry>
      <material
        name="">
        <color
          rgba="0.792156862745098 0.819607843137255 0.933333333333333 1" />
      </material>
    </visual>
    <collision>
      <origin
        xyz="0 0 0"
        rpy="0 0 0" />
      <geometry>
        <mesh
          filename="package://quadruped126/meshes/leg2_2.STL" />
      </geometry>
    </collision>
  </link>
  <joint
    name="leg2_2_joint"
    type="revolute">
    <origin
      xyz="0 0 0"
      rpy="1.5707963267949 0 1.0825960457001E-45" />
    <parent
      link="leg2-1" />
    <child
      link="leg2_2" />
    <axis
      xyz="0 0 -1" />
  </joint>
  <link
    name="leg2-3">
    <inertial>
      <origin
        xyz="0.112501231278765 -1.32724608035706E-05 0.110000027562196"
        rpy="0 0 0" />
      <mass
        value="0.422583469922353" />
      <inertia
        ixx="0.000984455636837685"
        ixy="-1.55958083378792E-08"
        ixz="-3.44244269604749E-05"
        iyy="0.00493486162041133"
        iyz="-2.80759527850035E-09"
        izz="0.00483276076809417" />
    </inertial>
    <visual>
      <origin
        xyz="0 0 0"
        rpy="0 0 0" />
      <geometry>
        <mesh
          filename="package://quadruped126/meshes/leg2-3.STL" />
      </geometry>
      <material
        name="">
        <color
          rgba="0.792156862745098 0.819607843137255 0.933333333333333 1" />
      </material>
    </visual>
    <collision>
      <origin
        xyz="0 0 0"
        rpy="0 0 0" />
      <geometry>
        <mesh
          filename="package://quadruped126/meshes/leg2-3.STL" />
      </geometry>
    </collision>
  </link>
  <joint
    name="leg2-3_joint"
    type="revolute">
    <origin
      xyz="0 0 0.1125"
      rpy="1.5707963267949 0 -1.5707963267949" />
    <parent
      link="leg2_2" />
    <child
      link="leg2-3" />
    <axis
      xyz="0 0 1" />
  </joint>
  <link
    name="leg2_4">
    <inertial>
      <origin
        xyz="0.144566617935963 -2.44398294269033E-07 0.0374204929051556"
        rpy="0 0 0" />
      <mass
        value="0.418000056329822" />
      <inertia
        ixx="0.00078609019228573"
        ixy="-3.04294738799536E-09"
        ixz="0.00125672996629427"
        iyy="0.00467553724369218"
        iyz="-1.72935126317538E-09"
        izz="0.00426725609243169" />
    </inertial>
    <visual>
      <origin
        xyz="0 0 0"
        rpy="0 0 0" />
      <geometry>
        <mesh
          filename="package://quadruped126/meshes/leg2_4.STL" />
      </geometry>
      <material
        name="">
        <color
          rgba="0.792156862745098 0.819607843137255 0.933333333333333 1" />
      </material>
    </visual>
    <collision>
      <origin
        xyz="0 0 0"
        rpy="0 0 0" />
      <geometry>
        <mesh
          filename="package://quadruped126/meshes/leg2_4.STL" />
      </geometry>
    </collision>
  </link>
  <joint
    name="leg2_4_joint"
    type="revolute">
    <origin
      xyz="0.225000000000001 0 0.109999999999998"
      rpy="0 7.75640276008131E-15 4.93432455388956E-16" />
    <parent
      link="leg2-3" />
    <child
      link="leg2_4" />
    <axis
      xyz="0 0 1" />
  </joint>
  <link
    name="leg3-1">
    <inertial>
      <origin
        xyz="9.23248237999497E-06 0.011029593618306 0.00343371080325942"
        rpy="0 0 0" />
      <mass
        value="0.13691684412558" />
      <inertia
        ixx="0.000229388410137999"
        ixy="-3.46713291271145E-08"
        ixz="4.50352127065379E-09"
        iyy="0.000216643147863624"
        iyz="6.85902749278864E-06"
        izz="0.000193488023621686" />
    </inertial>
    <visual>
      <origin
        xyz="0 0 0"
        rpy="0 0 0" />
      <geometry>
        <mesh
          filename="package://quadruped126/meshes/leg3-1.STL" />
      </geometry>
      <material
        name="">
        <color
          rgba="0.792156862745098 0.819607843137255 0.933333333333333 1" />
      </material>
    </visual>
    <collision>
      <origin
        xyz="0 0 0"
        rpy="0 0 0" />
      <geometry>
        <mesh
          filename="package://quadruped126/meshes/leg3-1.STL" />
      </geometry>
    </collision>
  </link>
  <joint
    name="leg3-1"
    type="revolute">
    <origin
      xyz="0.155 0.2 -0.0745"
      rpy="-1.16620065611886E-16 -8.28607345441151E-17 9.36811836742057E-17" />
    <parent
      link="base_link" />
    <child
      link="leg3-1" />
    <axis
      xyz="0 0 1" />
  </joint>
  <link
    name="leg3_2">
    <inertial>
      <origin
        xyz="-0.0117973861206462 -1.03683017630557E-05 0.109124835353205"
        rpy="0 0 0" />
      <mass
        value="0.139285865723005" />
      <inertia
        ixx="0.000230964268899531"
        ixy="-3.48586088600831E-08"
        ixz="7.22110905522496E-06"
        iyy="0.00024060897676921"
        iyz="6.60780844237386E-09"
        izz="0.000204330642068321" />
    </inertial>
    <visual>
      <origin
        xyz="0 0 0"
        rpy="0 0 0" />
      <geometry>
        <mesh
          filename="package://quadruped126/meshes/leg3_2.STL" />
      </geometry>
      <material
        name="">
        <color
          rgba="0.792156862745098 0.819607843137255 0.933333333333333 1" />
      </material>
    </visual>
    <collision>
      <origin
        xyz="0 0 0"
        rpy="0 0 0" />
      <geometry>
        <mesh
          filename="package://quadruped126/meshes/leg3_2.STL" />
      </geometry>
    </collision>
  </link>
  <joint
    name="leg3_2_joint"
    type="revolute">
    <origin
      xyz="0 0 0"
      rpy="1.5707963267949 0 3.14159265358979" />
    <parent
      link="leg3-1" />
    <child
      link="leg3_2" />
    <axis
      xyz="0 0 1" />
  </joint>
  <link
    name="leg3_3">
    <inertial>
      <origin
        xyz="0.112501231278764 -1.32724608037926E-05 0.110000027562196"
        rpy="0 0 0" />
      <mass
        value="0.422583469922348" />
      <inertia
        ixx="0.00098445563683767"
        ixy="-1.55958083335526E-08"
        ixz="-3.44244269604997E-05"
        iyy="0.00493486162041129"
        iyz="-2.80759527738509E-09"
        izz="0.00483276076809414" />
    </inertial>
    <visual>
      <origin
        xyz="0 0 0"
        rpy="0 0 0" />
      <geometry>
        <mesh
          filename="package://quadruped126/meshes/leg3_3.STL" />
      </geometry>
      <material
        name="">
        <color
          rgba="0.792156862745098 0.819607843137255 0.933333333333333 1" />
      </material>
    </visual>
    <collision>
      <origin
        xyz="0 0 0"
        rpy="0 0 0" />
      <geometry>
        <mesh
          filename="package://quadruped126/meshes/leg3_3.STL" />
      </geometry>
    </collision>
  </link>
  <joint
    name="leg3_3_joint"
    type="revolute">
    <origin
      xyz="0 0 0.1125"
      rpy="1.5707963267949 3.58579558626701E-16 -1.5707963267949" />
    <parent
      link="leg3_2" />
    <child
      link="leg3_3" />
    <axis
      xyz="0 0 -1" />
  </joint>
  <link
    name="leg3_4">
    <inertial>
      <origin
        xyz="0.14456661793596 -2.44398295157211E-07 0.0374204929107662"
        rpy="0 0 0" />
      <mass
        value="0.418000056329828" />
      <inertia
        ixx="0.000786091475635316"
        ixy="-3.04294744713543E-09"
        ixz="0.00125672996667006"
        iyy="0.00467553852704197"
        iyz="-1.72932822876566E-09"
        izz="0.00426725609243189" />
    </inertial>
    <visual>
      <origin
        xyz="0 0 0"
        rpy="0 0 0" />
      <geometry>
        <mesh
          filename="package://quadruped126/meshes/leg3_4.STL" />
      </geometry>
      <material
        name="">
        <color
          rgba="0.792156862745098 0.819607843137255 0.933333333333333 1" />
      </material>
    </visual>
    <collision>
      <origin
        xyz="0 0 0"
        rpy="0 0 0" />
      <geometry>
        <mesh
          filename="package://quadruped126/meshes/leg3_4.STL" />
      </geometry>
    </collision>
  </link>
  <joint
    name="leg3_4_joint"
    type="revolute">
    <origin
      xyz="0.225000000000001 0 0.11"
      rpy="1.4688239001149E-30 -6.97984565407256E-46 4.75199624238587E-16" />
    <parent
      link="leg3_3" />
    <child
      link="leg3_4" />
    <axis
      xyz="0 0 -1" />
  </joint>
  <link
    name="leg4-1">
    <inertial>
      <origin
        xyz="9.23248238214602E-06 0.0110295936183097 0.00343371080325674"
        rpy="0 0 0" />
      <mass
        value="0.136916844125614" />
      <inertia
        ixx="0.000229388410138032"
        ixy="-3.46713291306506E-08"
        ixz="4.50352127349385E-09"
        iyy="0.000216643147863653"
        iyz="6.85902749279376E-06"
        izz="0.000193488023621699" />
    </inertial>
    <visual>
      <origin
        xyz="0 0 0"
        rpy="0 0 0" />
      <geometry>
        <mesh
          filename="package://quadruped126/meshes/leg4-1.STL" />
      </geometry>
      <material
        name="">
        <color
          rgba="0.792156862745098 0.819607843137255 0.933333333333333 1" />
      </material>
    </visual>
    <collision>
      <origin
        xyz="0 0 0"
        rpy="0 0 0" />
      <geometry>
        <mesh
          filename="package://quadruped126/meshes/leg4-1.STL" />
      </geometry>
    </collision>
  </link>
  <joint
    name="leg4_1_joint"
    type="revolute">
    <origin
      xyz="-0.155 0.2 -0.0745"
      rpy="3.94745964311166E-15 -8.28607345441151E-17 9.36811836742057E-17" />
    <parent
      link="base_link" />
    <child
      link="leg4-1" />
    <axis
      xyz="0 0 1" />
  </joint>
  <link
    name="leg4_2">
    <inertial>
      <origin
        xyz="0.0117973861206458 1.03683017626879E-05 0.109124835353205"
        rpy="0 0 0" />
      <mass
        value="0.139285865723001" />
      <inertia
        ixx="0.000230964268899528"
        ixy="-3.48586088605111E-08"
        ixz="-7.22110905522453E-06"
        iyy="0.000240608976769207"
        iyz="-6.6078084421721E-09"
        izz="0.000204330642068317" />
    </inertial>
    <visual>
      <origin
        xyz="0 0 0"
        rpy="0 0 0" />
      <geometry>
        <mesh
          filename="package://quadruped126/meshes/leg4_2.STL" />
      </geometry>
      <material
        name="">
        <color
          rgba="0.792156862745098 0.819607843137255 0.933333333333333 1" />
      </material>
    </visual>
    <collision>
      <origin
        xyz="0 0 0"
        rpy="0 0 0" />
      <geometry>
        <mesh
          filename="package://quadruped126/meshes/leg4_2.STL" />
      </geometry>
    </collision>
  </link>
  <joint
    name="leg4_2_joint"
    type="revolute">
    <origin
      xyz="0 0 0"
      rpy="1.5707963267949 -4.41565975703188E-15 3.14159265358979" />
    <parent
      link="leg4-1" />
    <child
      link="leg4_2" />
    <axis
      xyz="0 0 1" />
  </joint>
  <link
    name="leg4_3">
    <inertial>
      <origin
        xyz="-0.112501231278764 1.3272460803071E-05 0.110000027562197"
        rpy="0 0 0" />
      <mass
        value="0.422583469922347" />
      <inertia
        ixx="0.000984455636837671"
        ixy="-1.55958083341559E-08"
        ixz="3.44244269605011E-05"
        iyy="0.00493486162041129"
        iyz="2.80759527783412E-09"
        izz="0.00483276076809414" />
    </inertial>
    <visual>
      <origin
        xyz="0 0 0"
        rpy="0 0 0" />
      <geometry>
        <mesh
          filename="package://quadruped126/meshes/leg4_3.STL" />
      </geometry>
      <material
        name="">
        <color
          rgba="0.792156862745098 0.819607843137255 0.933333333333333 1" />
      </material>
    </visual>
    <collision>
      <origin
        xyz="0 0 0"
        rpy="0 0 0" />
      <geometry>
        <mesh
          filename="package://quadruped126/meshes/leg4_3.STL" />
      </geometry>
    </collision>
  </link>
  <joint
    name="leg4_3_joint"
    type="revolute">
    <origin
      xyz="0 0 0.1125"
      rpy="1.5707963267949 -3.4237695371564E-15 1.57079632679489" />
    <parent
      link="leg4_2" />
    <child
      link="leg4_3" />
    <axis
      xyz="0 0 1" />
  </joint>
  <link
    name="leg4-4">
    <inertial>
      <origin
        xyz="0.144566617935977 -2.44398293214321E-07 0.0374204928991427"
        rpy="0 0 0" />
      <mass
        value="0.418000056329786" />
      <inertia
        ixx="0.000786089670519371"
        ixy="-3.04294735944315E-09"
        ixz="0.00125672996604183"
        iyy="0.00467553672192506"
        iyz="-1.72945349282626E-09"
        izz="0.00426725609243092" />
    </inertial>
    <visual>
      <origin
        xyz="0 0 0"
        rpy="0 0 0" />
      <geometry>
        <mesh
          filename="package://quadruped126/meshes/leg4-4.STL" />
      </geometry>
      <material
        name="">
        <color
          rgba="0.792156862745098 0.819607843137255 0.933333333333333 1" />
      </material>
    </visual>
    <collision>
      <origin
        xyz="0 0 0"
        rpy="0 0 0" />
      <geometry>
        <mesh
          filename="package://quadruped126/meshes/leg4-4.STL" />
      </geometry>
    </collision>
  </link>
  <joint
    name="leg4-4-joint"
    type="revolute">
    <origin
      xyz="-0.225000000000001 0 0.11"
      rpy="-2.31243732602241E-30 -2.46716227694479E-16 -3.14159265358979" />
    <parent
      link="leg4_3" />
    <child
      link="leg4-4" />
    <axis
      xyz="0 0 1" />
  </joint>
</robot>